[2024-12-23T13:27:38.687+0000] {taskinstance.py:1159} INFO - Dependencies all met for dep_context=non-requeueable deps ti=<TaskInstance: movie_etl_workflow.transform_data_rating manual__2024-12-23T13:21:52.282172+00:00 [queued]>
[2024-12-23T13:27:38.696+0000] {taskinstance.py:1159} INFO - Dependencies all met for dep_context=requeueable deps ti=<TaskInstance: movie_etl_workflow.transform_data_rating manual__2024-12-23T13:21:52.282172+00:00 [queued]>
[2024-12-23T13:27:38.696+0000] {taskinstance.py:1361} INFO - Starting attempt 2 of 2
[2024-12-23T13:27:38.708+0000] {taskinstance.py:1382} INFO - Executing <Task(BashOperator): transform_data_rating> on 2024-12-23 13:21:52.282172+00:00
[2024-12-23T13:27:38.713+0000] {standard_task_runner.py:57} INFO - Started process 2016 to run task
[2024-12-23T13:27:38.717+0000] {standard_task_runner.py:84} INFO - Running: ['***', 'tasks', 'run', 'movie_etl_workflow', 'transform_data_rating', 'manual__2024-12-23T13:21:52.282172+00:00', '--job-id', '153', '--raw', '--subdir', 'DAGS_FOLDER/movie_data_workflow.py', '--cfg-path', '/tmp/tmp87nrd1gb']
[2024-12-23T13:27:38.718+0000] {standard_task_runner.py:85} INFO - Job 153: Subtask transform_data_rating
[2024-12-23T13:27:38.735+0000] {warnings.py:109} WARNING - /home/***/.local/lib/python3.8/site-packages/***/settings.py:195: DeprecationWarning: The sql_alchemy_conn option in [core] has been moved to the sql_alchemy_conn option in [database] - the old setting has been used, but please update your config.
  SQL_ALCHEMY_CONN = conf.get("database", "SQL_ALCHEMY_CONN")

[2024-12-23T13:27:38.772+0000] {task_command.py:415} INFO - Running <TaskInstance: movie_etl_workflow.transform_data_rating manual__2024-12-23T13:21:52.282172+00:00 [running]> on host c498c9d7df3d
[2024-12-23T13:27:38.847+0000] {taskinstance.py:1660} INFO - Exporting env vars: AIRFLOW_CTX_DAG_OWNER='diinguyen' AIRFLOW_CTX_DAG_ID='movie_etl_workflow' AIRFLOW_CTX_TASK_ID='transform_data_rating' AIRFLOW_CTX_EXECUTION_DATE='2024-12-23T13:21:52.282172+00:00' AIRFLOW_CTX_TRY_NUMBER='2' AIRFLOW_CTX_DAG_RUN_ID='manual__2024-12-23T13:21:52.282172+00:00'
[2024-12-23T13:27:38.849+0000] {subprocess.py:63} INFO - Tmp dir root location: /tmp
[2024-12-23T13:27:38.850+0000] {subprocess.py:75} INFO - Running command: ['/bin/bash', '-c', 'python3 /opt/***/DE_project/ETL/transform/tranform_ratingdf.py']
[2024-12-23T13:27:38.859+0000] {subprocess.py:86} INFO - Output:
[2024-12-23T13:27:38.950+0000] {subprocess.py:93} INFO - python3: can't open file '/opt/***/DE_project/ETL/transform/tranform_ratingdf.py': [Errno 2] No such file or directory
[2024-12-23T13:27:38.954+0000] {subprocess.py:97} INFO - Command exited with return code 2
[2024-12-23T13:27:38.970+0000] {taskinstance.py:1943} ERROR - Task failed with exception
Traceback (most recent call last):
  File "/home/airflow/.local/lib/python3.8/site-packages/airflow/operators/bash.py", line 210, in execute
    raise AirflowException(
airflow.exceptions.AirflowException: Bash command failed. The command returned a non-zero exit code 2.
[2024-12-23T13:27:38.974+0000] {taskinstance.py:1400} INFO - Marking task as FAILED. dag_id=movie_etl_workflow, task_id=transform_data_rating, execution_date=20241223T132152, start_date=20241223T132738, end_date=20241223T132738
[2024-12-23T13:27:38.986+0000] {standard_task_runner.py:104} ERROR - Failed to execute job 153 for task transform_data_rating (Bash command failed. The command returned a non-zero exit code 2.; 2016)
[2024-12-23T13:27:39.019+0000] {local_task_job_runner.py:228} INFO - Task exited with return code 1
[2024-12-23T13:27:39.054+0000] {taskinstance.py:2784} INFO - 0 downstream tasks scheduled from follow-on schedule check
