[2024-12-23T13:19:42.068+0000] {warnings.py:109} WARNING - /home/***/.local/lib/python3.8/site-packages/***/utils/sqlalchemy.py:124: DeprecationWarning: The sql_alchemy_conn option in [core] has been moved to the sql_alchemy_conn option in [database] - the old setting has been used, but please update your config.
  return not conf.get("database", "sql_alchemy_conn").startswith("mssql")

[2024-12-23T13:19:42.091+0000] {taskinstance.py:1159} INFO - Dependencies all met for dep_context=non-requeueable deps ti=<TaskInstance: movie_etl_workflow.transform_data_rating scheduled__2024-12-22T00:00:00+00:00 [queued]>
[2024-12-23T13:19:42.108+0000] {taskinstance.py:1159} INFO - Dependencies all met for dep_context=requeueable deps ti=<TaskInstance: movie_etl_workflow.transform_data_rating scheduled__2024-12-22T00:00:00+00:00 [queued]>
[2024-12-23T13:19:42.108+0000] {taskinstance.py:1361} INFO - Starting attempt 1 of 2
[2024-12-23T13:19:42.129+0000] {taskinstance.py:1382} INFO - Executing <Task(BashOperator): transform_data_rating> on 2024-12-22 00:00:00+00:00
[2024-12-23T13:19:42.138+0000] {standard_task_runner.py:57} INFO - Started process 683 to run task
[2024-12-23T13:19:42.145+0000] {standard_task_runner.py:84} INFO - Running: ['***', 'tasks', 'run', 'movie_etl_workflow', 'transform_data_rating', 'scheduled__2024-12-22T00:00:00+00:00', '--job-id', '142', '--raw', '--subdir', 'DAGS_FOLDER/movie_data_workflow.py', '--cfg-path', '/tmp/tmpa2bi9a66']
[2024-12-23T13:19:42.147+0000] {standard_task_runner.py:85} INFO - Job 142: Subtask transform_data_rating
[2024-12-23T13:19:42.174+0000] {warnings.py:109} WARNING - /home/***/.local/lib/python3.8/site-packages/***/settings.py:195: DeprecationWarning: The sql_alchemy_conn option in [core] has been moved to the sql_alchemy_conn option in [database] - the old setting has been used, but please update your config.
  SQL_ALCHEMY_CONN = conf.get("database", "SQL_ALCHEMY_CONN")

[2024-12-23T13:19:42.249+0000] {task_command.py:415} INFO - Running <TaskInstance: movie_etl_workflow.transform_data_rating scheduled__2024-12-22T00:00:00+00:00 [running]> on host c498c9d7df3d
[2024-12-23T13:19:42.276+0000] {warnings.py:109} WARNING - /home/***/.local/lib/python3.8/site-packages/***/utils/sqlalchemy.py:124: DeprecationWarning: The sql_alchemy_conn option in [core] has been moved to the sql_alchemy_conn option in [database] - the old setting has been used, but please update your config.
  return not conf.get("database", "sql_alchemy_conn").startswith("mssql")

[2024-12-23T13:19:42.407+0000] {taskinstance.py:1660} INFO - Exporting env vars: AIRFLOW_CTX_DAG_OWNER='diinguyen' AIRFLOW_CTX_DAG_ID='movie_etl_workflow' AIRFLOW_CTX_TASK_ID='transform_data_rating' AIRFLOW_CTX_EXECUTION_DATE='2024-12-22T00:00:00+00:00' AIRFLOW_CTX_TRY_NUMBER='1' AIRFLOW_CTX_DAG_RUN_ID='scheduled__2024-12-22T00:00:00+00:00'
[2024-12-23T13:19:42.415+0000] {subprocess.py:63} INFO - Tmp dir root location: /tmp
[2024-12-23T13:19:42.421+0000] {subprocess.py:75} INFO - Running command: ['/bin/bash', '-c', 'python3 /opt/***/DE_project/ETL/transform/tranform_ratingdf.py']
[2024-12-23T13:19:42.442+0000] {subprocess.py:86} INFO - Output:
[2024-12-23T13:19:42.667+0000] {subprocess.py:93} INFO - python3: can't open file '/opt/***/DE_project/ETL/transform/tranform_ratingdf.py': [Errno 2] No such file or directory
[2024-12-23T13:19:42.673+0000] {subprocess.py:97} INFO - Command exited with return code 2
[2024-12-23T13:19:42.711+0000] {taskinstance.py:1943} ERROR - Task failed with exception
Traceback (most recent call last):
  File "/home/airflow/.local/lib/python3.8/site-packages/airflow/operators/bash.py", line 210, in execute
    raise AirflowException(
airflow.exceptions.AirflowException: Bash command failed. The command returned a non-zero exit code 2.
[2024-12-23T13:19:42.723+0000] {taskinstance.py:1400} INFO - Marking task as UP_FOR_RETRY. dag_id=movie_etl_workflow, task_id=transform_data_rating, execution_date=20241222T000000, start_date=20241223T131942, end_date=20241223T131942
[2024-12-23T13:19:42.755+0000] {standard_task_runner.py:104} ERROR - Failed to execute job 142 for task transform_data_rating (Bash command failed. The command returned a non-zero exit code 2.; 683)
[2024-12-23T13:19:42.770+0000] {local_task_job_runner.py:228} INFO - Task exited with return code 1
[2024-12-23T13:19:42.828+0000] {taskinstance.py:2784} INFO - 0 downstream tasks scheduled from follow-on schedule check
