[2024-12-24T06:04:57.430+0000] {taskinstance.py:1159} INFO - Dependencies all met for dep_context=non-requeueable deps ti=<TaskInstance: movie_etl_workflow.fetch_movie_data manual__2024-12-24T06:04:55.365001+00:00 [queued]>
[2024-12-24T06:04:57.446+0000] {taskinstance.py:1159} INFO - Dependencies all met for dep_context=requeueable deps ti=<TaskInstance: movie_etl_workflow.fetch_movie_data manual__2024-12-24T06:04:55.365001+00:00 [queued]>
[2024-12-24T06:04:57.446+0000] {taskinstance.py:1361} INFO - Starting attempt 1 of 2
[2024-12-24T06:04:57.472+0000] {taskinstance.py:1382} INFO - Executing <Task(BashOperator): fetch_movie_data> on 2024-12-24 06:04:55.365001+00:00
[2024-12-24T06:04:57.477+0000] {standard_task_runner.py:57} INFO - Started process 452 to run task
[2024-12-24T06:04:57.482+0000] {standard_task_runner.py:84} INFO - Running: ['***', 'tasks', 'run', 'movie_etl_workflow', 'fetch_movie_data', 'manual__2024-12-24T06:04:55.365001+00:00', '--job-id', '190', '--raw', '--subdir', 'DAGS_FOLDER/movie_data_workflow.py', '--cfg-path', '/tmp/tmpkxclvqlb']
[2024-12-24T06:04:57.483+0000] {standard_task_runner.py:85} INFO - Job 190: Subtask fetch_movie_data
[2024-12-24T06:04:57.507+0000] {warnings.py:109} WARNING - /home/***/.local/lib/python3.8/site-packages/***/settings.py:195: DeprecationWarning: The sql_alchemy_conn option in [core] has been moved to the sql_alchemy_conn option in [database] - the old setting has been used, but please update your config.
  SQL_ALCHEMY_CONN = conf.get("database", "SQL_ALCHEMY_CONN")

[2024-12-24T06:04:57.564+0000] {task_command.py:415} INFO - Running <TaskInstance: movie_etl_workflow.fetch_movie_data manual__2024-12-24T06:04:55.365001+00:00 [running]> on host 4170f75a0525
[2024-12-24T06:04:57.672+0000] {taskinstance.py:1660} INFO - Exporting env vars: AIRFLOW_CTX_DAG_OWNER='diinguyen' AIRFLOW_CTX_DAG_ID='movie_etl_workflow' AIRFLOW_CTX_TASK_ID='fetch_movie_data' AIRFLOW_CTX_EXECUTION_DATE='2024-12-24T06:04:55.365001+00:00' AIRFLOW_CTX_TRY_NUMBER='1' AIRFLOW_CTX_DAG_RUN_ID='manual__2024-12-24T06:04:55.365001+00:00'
[2024-12-24T06:04:57.674+0000] {subprocess.py:63} INFO - Tmp dir root location: /tmp
[2024-12-24T06:04:57.676+0000] {subprocess.py:75} INFO - Running command: ['/bin/bash', '-c', 'python3 /opt/***/DE_project/ETL/extract/API_movie_Themoviedb.py']
[2024-12-24T06:04:57.689+0000] {subprocess.py:86} INFO - Output:
[2024-12-24T06:06:34.046+0000] {subprocess.py:93} INFO - Fetched data for page 1
[2024-12-24T06:06:34.048+0000] {subprocess.py:93} INFO - Fetched data for page 2
[2024-12-24T06:06:34.048+0000] {subprocess.py:93} INFO - Fetched data for page 3
[2024-12-24T06:06:34.050+0000] {subprocess.py:93} INFO - Fetched data for page 4
[2024-12-24T06:06:34.053+0000] {subprocess.py:93} INFO - Fetched data for page 5
[2024-12-24T06:06:34.054+0000] {subprocess.py:93} INFO - Fetched data for page 6
[2024-12-24T06:06:34.055+0000] {subprocess.py:93} INFO - Fetched data for page 7
[2024-12-24T06:06:34.056+0000] {subprocess.py:93} INFO - Fetched data for page 8
[2024-12-24T06:06:34.057+0000] {subprocess.py:93} INFO - Fetched data for page 9
[2024-12-24T06:06:34.058+0000] {subprocess.py:93} INFO - Fetched data for page 10
[2024-12-24T06:06:34.059+0000] {subprocess.py:93} INFO - Fetched data for page 11
[2024-12-24T06:06:34.060+0000] {subprocess.py:93} INFO - Fetched data for page 12
[2024-12-24T06:06:34.064+0000] {subprocess.py:93} INFO - Fetched data for page 13
[2024-12-24T06:06:34.068+0000] {subprocess.py:93} INFO - Failed to fetch details for movie ID 1118028 (attempt 1): HTTPSConnectionPool(host='api.themoviedb.org', port=443): Max retries exceeded with url: /3/movie/1118028?api_key=9fb9d335431a9f6007701ac905fcd5e5 (Caused by NewConnectionError('<urllib3.connection.HTTPSConnection object at 0x7ff04508d400>: Failed to establish a new connection: [Errno -2] Name or service not known'))
[2024-12-24T06:06:34.070+0000] {subprocess.py:93} INFO - Failed to fetch details for movie ID 1118028 (attempt 2): HTTPSConnectionPool(host='api.themoviedb.org', port=443): Max retries exceeded with url: /3/movie/1118028?api_key=9fb9d335431a9f6007701ac905fcd5e5 (Caused by NewConnectionError('<urllib3.connection.HTTPSConnection object at 0x7ff04508d0d0>: Failed to establish a new connection: [Errno -2] Name or service not known'))
[2024-12-24T06:06:34.072+0000] {subprocess.py:93} INFO - Failed to fetch details for movie ID 1118028 (attempt 3): HTTPSConnectionPool(host='api.themoviedb.org', port=443): Max retries exceeded with url: /3/movie/1118028?api_key=9fb9d335431a9f6007701ac905fcd5e5 (Caused by NewConnectionError('<urllib3.connection.HTTPSConnection object at 0x7ff04508da60>: Failed to establish a new connection: [Errno -2] Name or service not known'))
[2024-12-24T06:06:34.075+0000] {subprocess.py:93} INFO - Failed to fetch details for movie ID 1118028 after 3 attempts.
[2024-12-24T06:06:34.077+0000] {subprocess.py:93} INFO - Failed to fetch details for movie ID 1075676 (attempt 1): HTTPSConnectionPool(host='api.themoviedb.org', port=443): Max retries exceeded with url: /3/movie/1075676?api_key=9fb9d335431a9f6007701ac905fcd5e5 (Caused by NewConnectionError('<urllib3.connection.HTTPSConnection object at 0x7ff04508d400>: Failed to establish a new connection: [Errno -2] Name or service not known'))
[2024-12-24T06:06:34.078+0000] {subprocess.py:93} INFO - Failed to fetch details for movie ID 1075676 (attempt 2): HTTPSConnectionPool(host='api.themoviedb.org', port=443): Max retries exceeded with url: /3/movie/1075676?api_key=9fb9d335431a9f6007701ac905fcd5e5 (Caused by NewConnectionError('<urllib3.connection.HTTPSConnection object at 0x7ff04508d0d0>: Failed to establish a new connection: [Errno -2] Name or service not known'))
[2024-12-24T06:06:34.081+0000] {subprocess.py:93} INFO - Failed to fetch details for movie ID 1075676 (attempt 3): HTTPSConnectionPool(host='api.themoviedb.org', port=443): Max retries exceeded with url: /3/movie/1075676?api_key=9fb9d335431a9f6007701ac905fcd5e5 (Caused by NewConnectionError('<urllib3.connection.HTTPSConnection object at 0x7ff04508da60>: Failed to establish a new connection: [Errno -2] Name or service not known'))
[2024-12-24T06:06:34.082+0000] {subprocess.py:93} INFO - Failed to fetch details for movie ID 1075676 after 3 attempts.
[2024-12-24T06:06:34.083+0000] {subprocess.py:93} INFO - Failed to fetch details for movie ID 792614 (attempt 1): HTTPSConnectionPool(host='api.themoviedb.org', port=443): Max retries exceeded with url: /3/movie/792614?api_key=9fb9d335431a9f6007701ac905fcd5e5 (Caused by NewConnectionError('<urllib3.connection.HTTPSConnection object at 0x7ff04508d400>: Failed to establish a new connection: [Errno -2] Name or service not known'))
[2024-12-24T06:06:34.084+0000] {subprocess.py:93} INFO - Failed to fetch details for movie ID 792614 (attempt 2): HTTPSConnectionPool(host='api.themoviedb.org', port=443): Max retries exceeded with url: /3/movie/792614?api_key=9fb9d335431a9f6007701ac905fcd5e5 (Caused by NewConnectionError('<urllib3.connection.HTTPSConnection object at 0x7ff04508d0d0>: Failed to establish a new connection: [Errno -2] Name or service not known'))
[2024-12-24T06:06:34.085+0000] {subprocess.py:93} INFO - Failed to fetch details for movie ID 792614 (attempt 3): HTTPSConnectionPool(host='api.themoviedb.org', port=443): Max retries exceeded with url: /3/movie/792614?api_key=9fb9d335431a9f6007701ac905fcd5e5 (Caused by NewConnectionError('<urllib3.connection.HTTPSConnection object at 0x7ff04508da60>: Failed to establish a new connection: [Errno -2] Name or service not known'))
[2024-12-24T06:06:34.087+0000] {subprocess.py:93} INFO - Failed to fetch details for movie ID 792614 after 3 attempts.
[2024-12-24T06:06:34.091+0000] {subprocess.py:93} INFO - Failed to fetch details for movie ID 122 (attempt 1): HTTPSConnectionPool(host='api.themoviedb.org', port=443): Max retries exceeded with url: /3/movie/122?api_key=9fb9d335431a9f6007701ac905fcd5e5 (Caused by NewConnectionError('<urllib3.connection.HTTPSConnection object at 0x7ff04508d400>: Failed to establish a new connection: [Errno -2] Name or service not known'))
[2024-12-24T06:06:34.092+0000] {subprocess.py:93} INFO - Failed to fetch details for movie ID 122 (attempt 2): HTTPSConnectionPool(host='api.themoviedb.org', port=443): Max retries exceeded with url: /3/movie/122?api_key=9fb9d335431a9f6007701ac905fcd5e5 (Caused by NewConnectionError('<urllib3.connection.HTTPSConnection object at 0x7ff04508d0d0>: Failed to establish a new connection: [Errno -2] Name or service not known'))
[2024-12-24T06:06:34.094+0000] {subprocess.py:93} INFO - Failed to fetch details for movie ID 122 (attempt 3): HTTPSConnectionPool(host='api.themoviedb.org', port=443): Max retries exceeded with url: /3/movie/122?api_key=9fb9d335431a9f6007701ac905fcd5e5 (Caused by NewConnectionError('<urllib3.connection.HTTPSConnection object at 0x7ff04508da60>: Failed to establish a new connection: [Errno -2] Name or service not known'))
[2024-12-24T06:06:34.095+0000] {subprocess.py:93} INFO - Failed to fetch details for movie ID 122 after 3 attempts.
[2024-12-24T06:06:34.097+0000] {subprocess.py:93} INFO - Failed to fetch details for movie ID 1306764 (attempt 1): HTTPSConnectionPool(host='api.themoviedb.org', port=443): Max retries exceeded with url: /3/movie/1306764?api_key=9fb9d335431a9f6007701ac905fcd5e5 (Caused by NewConnectionError('<urllib3.connection.HTTPSConnection object at 0x7ff04508d400>: Failed to establish a new connection: [Errno -2] Name or service not known'))
[2024-12-24T06:06:34.098+0000] {subprocess.py:93} INFO - Failed to fetch details for movie ID 1306764 (attempt 2): HTTPSConnectionPool(host='api.themoviedb.org', port=443): Max retries exceeded with url: /3/movie/1306764?api_key=9fb9d335431a9f6007701ac905fcd5e5 (Caused by NewConnectionError('<urllib3.connection.HTTPSConnection object at 0x7ff04508d0d0>: Failed to establish a new connection: [Errno -2] Name or service not known'))
[2024-12-24T06:06:34.106+0000] {subprocess.py:93} INFO - Failed to fetch details for movie ID 1306764 (attempt 3): HTTPSConnectionPool(host='api.themoviedb.org', port=443): Max retries exceeded with url: /3/movie/1306764?api_key=9fb9d335431a9f6007701ac905fcd5e5 (Caused by NewConnectionError('<urllib3.connection.HTTPSConnection object at 0x7ff04508da60>: Failed to establish a new connection: [Errno -2] Name or service not known'))
[2024-12-24T06:06:34.107+0000] {subprocess.py:93} INFO - Failed to fetch details for movie ID 1306764 after 3 attempts.
[2024-12-24T06:06:34.108+0000] {subprocess.py:93} INFO - Failed to fetch details for movie ID 1160018 (attempt 1): HTTPSConnectionPool(host='api.themoviedb.org', port=443): Max retries exceeded with url: /3/movie/1160018?api_key=9fb9d335431a9f6007701ac905fcd5e5 (Caused by NewConnectionError('<urllib3.connection.HTTPSConnection object at 0x7ff04508d400>: Failed to establish a new connection: [Errno -2] Name or service not known'))
[2024-12-24T06:06:34.110+0000] {subprocess.py:93} INFO - Failed to fetch details for movie ID 1160018 (attempt 2): HTTPSConnectionPool(host='api.themoviedb.org', port=443): Max retries exceeded with url: /3/movie/1160018?api_key=9fb9d335431a9f6007701ac905fcd5e5 (Caused by NewConnectionError('<urllib3.connection.HTTPSConnection object at 0x7ff04508d0d0>: Failed to establish a new connection: [Errno -2] Name or service not known'))
[2024-12-24T06:06:34.111+0000] {subprocess.py:93} INFO - Failed to fetch details for movie ID 1160018 (attempt 3): HTTPSConnectionPool(host='api.themoviedb.org', port=443): Max retries exceeded with url: /3/movie/1160018?api_key=9fb9d335431a9f6007701ac905fcd5e5 (Caused by NewConnectionError('<urllib3.connection.HTTPSConnection object at 0x7ff04508da60>: Failed to establish a new connection: [Errno -2] Name or service not known'))
[2024-12-24T06:06:34.112+0000] {subprocess.py:93} INFO - Failed to fetch details for movie ID 1160018 after 3 attempts.
[2024-12-24T06:06:34.112+0000] {subprocess.py:93} INFO - Failed to fetch details for movie ID 354912 (attempt 1): HTTPSConnectionPool(host='api.themoviedb.org', port=443): Max retries exceeded with url: /3/movie/354912?api_key=9fb9d335431a9f6007701ac905fcd5e5 (Caused by NewConnectionError('<urllib3.connection.HTTPSConnection object at 0x7ff04508d400>: Failed to establish a new connection: [Errno -2] Name or service not known'))
[2024-12-24T06:06:34.285+0000] {subprocess.py:93} INFO - Failed to fetch details for movie ID 354912 (attempt 2): HTTPSConnectionPool(host='api.themoviedb.org', port=443): Max retries exceeded with url: /3/movie/354912?api_key=9fb9d335431a9f6007701ac905fcd5e5 (Caused by NewConnectionError('<urllib3.connection.HTTPSConnection object at 0x7ff04508d0d0>: Failed to establish a new connection: [Errno -2] Name or service not known'))
[2024-12-24T06:06:34.286+0000] {subprocess.py:93} INFO - Failed to fetch details for movie ID 354912 (attempt 3): HTTPSConnectionPool(host='api.themoviedb.org', port=443): Max retries exceeded with url: /3/movie/354912?api_key=9fb9d335431a9f6007701ac905fcd5e5 (Caused by NewConnectionError('<urllib3.connection.HTTPSConnection object at 0x7ff04508da60>: Failed to establish a new connection: [Errno -2] Name or service not known'))
[2024-12-24T06:06:34.286+0000] {subprocess.py:93} INFO - Failed to fetch details for movie ID 354912 after 3 attempts.
[2024-12-24T06:06:34.287+0000] {subprocess.py:93} INFO - Failed to fetch details for movie ID 58 (attempt 1): HTTPSConnectionPool(host='api.themoviedb.org', port=443): Max retries exceeded with url: /3/movie/58?api_key=9fb9d335431a9f6007701ac905fcd5e5 (Caused by NewConnectionError('<urllib3.connection.HTTPSConnection object at 0x7ff04508d0d0>: Failed to establish a new connection: [Errno -2] Name or service not known'))
[2024-12-24T06:06:34.287+0000] {subprocess.py:93} INFO - Failed to fetch details for movie ID 58 (attempt 2): HTTPSConnectionPool(host='api.themoviedb.org', port=443): Max retries exceeded with url: /3/movie/58?api_key=9fb9d335431a9f6007701ac905fcd5e5 (Caused by NewConnectionError('<urllib3.connection.HTTPSConnection object at 0x7ff04508d070>: Failed to establish a new connection: [Errno -2] Name or service not known'))
[2024-12-24T06:06:34.288+0000] {subprocess.py:93} INFO - Failed to fetch details for movie ID 58 (attempt 3): HTTPSConnectionPool(host='api.themoviedb.org', port=443): Max retries exceeded with url: /3/movie/58?api_key=9fb9d335431a9f6007701ac905fcd5e5 (Caused by NewConnectionError('<urllib3.connection.HTTPSConnection object at 0x7ff04508da60>: Failed to establish a new connection: [Errno -2] Name or service not known'))
[2024-12-24T06:06:34.290+0000] {subprocess.py:93} INFO - Failed to fetch details for movie ID 58 after 3 attempts.
[2024-12-24T06:06:34.291+0000] {subprocess.py:93} INFO - Failed to fetch details for movie ID 475557 (attempt 1): HTTPSConnectionPool(host='api.themoviedb.org', port=443): Max retries exceeded with url: /3/movie/475557?api_key=9fb9d335431a9f6007701ac905fcd5e5 (Caused by NewConnectionError('<urllib3.connection.HTTPSConnection object at 0x7ff04508d880>: Failed to establish a new connection: [Errno -2] Name or service not known'))
[2024-12-24T06:06:34.292+0000] {subprocess.py:93} INFO - Failed to fetch details for movie ID 475557 (attempt 2): HTTPSConnectionPool(host='api.themoviedb.org', port=443): Max retries exceeded with url: /3/movie/475557?api_key=9fb9d335431a9f6007701ac905fcd5e5 (Caused by NewConnectionError('<urllib3.connection.HTTPSConnection object at 0x7ff04508d070>: Failed to establish a new connection: [Errno -2] Name or service not known'))
[2024-12-24T06:06:34.292+0000] {subprocess.py:93} INFO - Failed to fetch details for movie ID 475557 (attempt 3): HTTPSConnectionPool(host='api.themoviedb.org', port=443): Max retries exceeded with url: /3/movie/475557?api_key=9fb9d335431a9f6007701ac905fcd5e5 (Caused by NewConnectionError('<urllib3.connection.HTTPSConnection object at 0x7ff04508da60>: Failed to establish a new connection: [Errno -2] Name or service not known'))
[2024-12-24T06:06:34.293+0000] {subprocess.py:93} INFO - Failed to fetch details for movie ID 475557 after 3 attempts.
[2024-12-24T06:06:34.295+0000] {subprocess.py:93} INFO - Failed to fetch details for movie ID 863 (attempt 1): HTTPSConnectionPool(host='api.themoviedb.org', port=443): Max retries exceeded with url: /3/movie/863?api_key=9fb9d335431a9f6007701ac905fcd5e5 (Caused by NewConnectionError('<urllib3.connection.HTTPSConnection object at 0x7ff04508d880>: Failed to establish a new connection: [Errno -2] Name or service not known'))
[2024-12-24T06:06:34.296+0000] {subprocess.py:93} INFO - Failed to fetch details for movie ID 863 (attempt 2): HTTPSConnectionPool(host='api.themoviedb.org', port=443): Max retries exceeded with url: /3/movie/863?api_key=9fb9d335431a9f6007701ac905fcd5e5 (Caused by NewConnectionError('<urllib3.connection.HTTPSConnection object at 0x7ff04508d070>: Failed to establish a new connection: [Errno -2] Name or service not known'))
[2024-12-24T06:06:34.298+0000] {subprocess.py:93} INFO - Failed to fetch details for movie ID 863 (attempt 3): HTTPSConnectionPool(host='api.themoviedb.org', port=443): Max retries exceeded with url: /3/movie/863?api_key=9fb9d335431a9f6007701ac905fcd5e5 (Caused by NewConnectionError('<urllib3.connection.HTTPSConnection object at 0x7ff04508da60>: Failed to establish a new connection: [Errno -2] Name or service not known'))
[2024-12-24T06:06:34.300+0000] {subprocess.py:93} INFO - Failed to fetch details for movie ID 863 after 3 attempts.
[2024-12-24T06:06:34.301+0000] {subprocess.py:93} INFO - Failed to fetch details for movie ID 9732 (attempt 1): HTTPSConnectionPool(host='api.themoviedb.org', port=443): Max retries exceeded with url: /3/movie/9732?api_key=9fb9d335431a9f6007701ac905fcd5e5 (Caused by NewConnectionError('<urllib3.connection.HTTPSConnection object at 0x7ff04508d880>: Failed to establish a new connection: [Errno -2] Name or service not known'))
[2024-12-24T06:06:34.303+0000] {subprocess.py:93} INFO - Failed to fetch details for movie ID 9732 (attempt 2): HTTPSConnectionPool(host='api.themoviedb.org', port=443): Max retries exceeded with url: /3/movie/9732?api_key=9fb9d335431a9f6007701ac905fcd5e5 (Caused by NewConnectionError('<urllib3.connection.HTTPSConnection object at 0x7ff04508d070>: Failed to establish a new connection: [Errno -2] Name or service not known'))
[2024-12-24T06:06:34.304+0000] {subprocess.py:93} INFO - Failed to fetch details for movie ID 9732 (attempt 3): HTTPSConnectionPool(host='api.themoviedb.org', port=443): Max retries exceeded with url: /3/movie/9732?api_key=9fb9d335431a9f6007701ac905fcd5e5 (Caused by NewConnectionError('<urllib3.connection.HTTPSConnection object at 0x7ff04508da60>: Failed to establish a new connection: [Errno -2] Name or service not known'))
[2024-12-24T06:06:34.304+0000] {subprocess.py:93} INFO - Failed to fetch details for movie ID 9732 after 3 attempts.
[2024-12-24T06:06:34.305+0000] {subprocess.py:93} INFO - Failed to fetch details for movie ID 585 (attempt 1): HTTPSConnectionPool(host='api.themoviedb.org', port=443): Max retries exceeded with url: /3/movie/585?api_key=9fb9d335431a9f6007701ac905fcd5e5 (Caused by NewConnectionError('<urllib3.connection.HTTPSConnection object at 0x7ff04508d880>: Failed to establish a new connection: [Errno -2] Name or service not known'))
[2024-12-24T06:06:34.306+0000] {subprocess.py:93} INFO - Failed to fetch details for movie ID 585 (attempt 2): HTTPSConnectionPool(host='api.themoviedb.org', port=443): Max retries exceeded with url: /3/movie/585?api_key=9fb9d335431a9f6007701ac905fcd5e5 (Caused by NewConnectionError('<urllib3.connection.HTTPSConnection object at 0x7ff04508d070>: Failed to establish a new connection: [Errno -2] Name or service not known'))
[2024-12-24T06:06:34.306+0000] {subprocess.py:93} INFO - Failed to fetch details for movie ID 585 (attempt 3): HTTPSConnectionPool(host='api.themoviedb.org', port=443): Max retries exceeded with url: /3/movie/585?api_key=9fb9d335431a9f6007701ac905fcd5e5 (Caused by NewConnectionError('<urllib3.connection.HTTPSConnection object at 0x7ff04508da60>: Failed to establish a new connection: [Errno -2] Name or service not known'))
[2024-12-24T06:06:34.307+0000] {subprocess.py:93} INFO - Failed to fetch details for movie ID 585 after 3 attempts.
[2024-12-24T06:06:34.310+0000] {subprocess.py:93} INFO - Failed to fetch details for movie ID 82702 (attempt 1): HTTPSConnectionPool(host='api.themoviedb.org', port=443): Max retries exceeded with url: /3/movie/82702?api_key=9fb9d335431a9f6007701ac905fcd5e5 (Caused by NewConnectionError('<urllib3.connection.HTTPSConnection object at 0x7ff04508d880>: Failed to establish a new connection: [Errno -2] Name or service not known'))
[2024-12-24T06:06:34.310+0000] {subprocess.py:93} INFO - Failed to fetch details for movie ID 82702 (attempt 2): HTTPSConnectionPool(host='api.themoviedb.org', port=443): Max retries exceeded with url: /3/movie/82702?api_key=9fb9d335431a9f6007701ac905fcd5e5 (Caused by NewConnectionError('<urllib3.connection.HTTPSConnection object at 0x7ff04508d070>: Failed to establish a new connection: [Errno -2] Name or service not known'))
[2024-12-24T06:06:34.314+0000] {subprocess.py:93} INFO - Failed to fetch details for movie ID 82702 (attempt 3): HTTPSConnectionPool(host='api.themoviedb.org', port=443): Max retries exceeded with url: /3/movie/82702?api_key=9fb9d335431a9f6007701ac905fcd5e5 (Caused by NewConnectionError('<urllib3.connection.HTTPSConnection object at 0x7ff04508da60>: Failed to establish a new connection: [Errno -2] Name or service not known'))
[2024-12-24T06:06:34.315+0000] {subprocess.py:93} INFO - Failed to fetch details for movie ID 82702 after 3 attempts.
[2024-12-24T06:06:34.486+0000] {subprocess.py:93} INFO - Failed to fetch details for movie ID 337404 (attempt 1): HTTPSConnectionPool(host='api.themoviedb.org', port=443): Max retries exceeded with url: /3/movie/337404?api_key=9fb9d335431a9f6007701ac905fcd5e5 (Caused by NewConnectionError('<urllib3.connection.HTTPSConnection object at 0x7ff04508d880>: Failed to establish a new connection: [Errno -2] Name or service not known'))
[2024-12-24T06:06:34.486+0000] {subprocess.py:93} INFO - Failed to fetch details for movie ID 337404 (attempt 2): HTTPSConnectionPool(host='api.themoviedb.org', port=443): Max retries exceeded with url: /3/movie/337404?api_key=9fb9d335431a9f6007701ac905fcd5e5 (Caused by NewConnectionError('<urllib3.connection.HTTPSConnection object at 0x7ff04508d070>: Failed to establish a new connection: [Errno -2] Name or service not known'))
[2024-12-24T06:06:34.487+0000] {subprocess.py:93} INFO - Failed to fetch details for movie ID 337404 (attempt 3): HTTPSConnectionPool(host='api.themoviedb.org', port=443): Max retries exceeded with url: /3/movie/337404?api_key=9fb9d335431a9f6007701ac905fcd5e5 (Caused by NewConnectionError('<urllib3.connection.HTTPSConnection object at 0x7ff04508d880>: Failed to establish a new connection: [Errno -2] Name or service not known'))
[2024-12-24T06:06:34.487+0000] {subprocess.py:93} INFO - Failed to fetch details for movie ID 337404 after 3 attempts.
[2024-12-24T06:06:34.488+0000] {subprocess.py:93} INFO - Failed to fetch details for movie ID 76341 (attempt 1): HTTPSConnectionPool(host='api.themoviedb.org', port=443): Max retries exceeded with url: /3/movie/76341?api_key=9fb9d335431a9f6007701ac905fcd5e5 (Caused by NewConnectionError('<urllib3.connection.HTTPSConnection object at 0x7ff04508dd90>: Failed to establish a new connection: [Errno -2] Name or service not known'))
[2024-12-24T06:06:34.488+0000] {subprocess.py:93} INFO - Failed to fetch details for movie ID 76341 (attempt 2): HTTPSConnectionPool(host='api.themoviedb.org', port=443): Max retries exceeded with url: /3/movie/76341?api_key=9fb9d335431a9f6007701ac905fcd5e5 (Caused by NewConnectionError('<urllib3.connection.HTTPSConnection object at 0x7ff04508d070>: Failed to establish a new connection: [Errno -2] Name or service not known'))
[2024-12-24T06:06:34.489+0000] {subprocess.py:93} INFO - Failed to fetch details for movie ID 76341 (attempt 3): HTTPSConnectionPool(host='api.themoviedb.org', port=443): Max retries exceeded with url: /3/movie/76341?api_key=9fb9d335431a9f6007701ac905fcd5e5 (Caused by NewConnectionError('<urllib3.connection.HTTPSConnection object at 0x7ff04508d0d0>: Failed to establish a new connection: [Errno -2] Name or service not known'))
[2024-12-24T06:06:34.490+0000] {subprocess.py:93} INFO - Failed to fetch details for movie ID 76341 after 3 attempts.
[2024-12-24T06:06:34.490+0000] {subprocess.py:93} INFO - Failed to fetch details for movie ID 809 (attempt 1): HTTPSConnectionPool(host='api.themoviedb.org', port=443): Max retries exceeded with url: /3/movie/809?api_key=9fb9d335431a9f6007701ac905fcd5e5 (Caused by NewConnectionError('<urllib3.connection.HTTPSConnection object at 0x7ff04508dd90>: Failed to establish a new connection: [Errno -2] Name or service not known'))
[2024-12-24T06:06:34.491+0000] {subprocess.py:93} INFO - Failed to fetch details for movie ID 809 (attempt 2): HTTPSConnectionPool(host='api.themoviedb.org', port=443): Max retries exceeded with url: /3/movie/809?api_key=9fb9d335431a9f6007701ac905fcd5e5 (Caused by NewConnectionError('<urllib3.connection.HTTPSConnection object at 0x7ff04508d070>: Failed to establish a new connection: [Errno -2] Name or service not known'))
[2024-12-24T06:06:34.491+0000] {subprocess.py:93} INFO - Failed to fetch details for movie ID 809 (attempt 3): HTTPSConnectionPool(host='api.themoviedb.org', port=443): Max retries exceeded with url: /3/movie/809?api_key=9fb9d335431a9f6007701ac905fcd5e5 (Caused by NewConnectionError('<urllib3.connection.HTTPSConnection object at 0x7ff04508d0d0>: Failed to establish a new connection: [Errno -2] Name or service not known'))
[2024-12-24T06:06:34.492+0000] {subprocess.py:93} INFO - Failed to fetch details for movie ID 809 after 3 attempts.
[2024-12-24T06:06:34.493+0000] {subprocess.py:93} INFO - Failed to fetch details for movie ID 882598 (attempt 1): HTTPSConnectionPool(host='api.themoviedb.org', port=443): Max retries exceeded with url: /3/movie/882598?api_key=9fb9d335431a9f6007701ac905fcd5e5 (Caused by NewConnectionError('<urllib3.connection.HTTPSConnection object at 0x7ff04508dd90>: Failed to establish a new connection: [Errno -2] Name or service not known'))
[2024-12-24T06:06:34.494+0000] {subprocess.py:93} INFO - Failed to fetch details for movie ID 882598 (attempt 2): HTTPSConnectionPool(host='api.themoviedb.org', port=443): Max retries exceeded with url: /3/movie/882598?api_key=9fb9d335431a9f6007701ac905fcd5e5 (Caused by NewConnectionError('<urllib3.connection.HTTPSConnection object at 0x7ff04508d070>: Failed to establish a new connection: [Errno -2] Name or service not known'))
[2024-12-24T06:06:34.494+0000] {subprocess.py:93} INFO - Failed to fetch details for movie ID 882598 (attempt 3): HTTPSConnectionPool(host='api.themoviedb.org', port=443): Max retries exceeded with url: /3/movie/882598?api_key=9fb9d335431a9f6007701ac905fcd5e5 (Caused by NewConnectionError('<urllib3.connection.HTTPSConnection object at 0x7ff04508d0d0>: Failed to establish a new connection: [Errno -2] Name or service not known'))
[2024-12-24T06:06:34.495+0000] {subprocess.py:93} INFO - Failed to fetch details for movie ID 882598 after 3 attempts.
[2024-12-24T06:06:34.496+0000] {subprocess.py:93} INFO - Failed to fetch details for movie ID 18785 (attempt 1): HTTPSConnectionPool(host='api.themoviedb.org', port=443): Max retries exceeded with url: /3/movie/18785?api_key=9fb9d335431a9f6007701ac905fcd5e5 (Caused by NewConnectionError('<urllib3.connection.HTTPSConnection object at 0x7ff04508dd90>: Failed to establish a new connection: [Errno -2] Name or service not known'))
[2024-12-24T06:06:34.498+0000] {subprocess.py:93} INFO - Failed to fetch details for movie ID 18785 (attempt 2): HTTPSConnectionPool(host='api.themoviedb.org', port=443): Max retries exceeded with url: /3/movie/18785?api_key=9fb9d335431a9f6007701ac905fcd5e5 (Caused by NewConnectionError('<urllib3.connection.HTTPSConnection object at 0x7ff04508d070>: Failed to establish a new connection: [Errno -2] Name or service not known'))
[2024-12-24T06:06:34.499+0000] {subprocess.py:93} INFO - Failed to fetch details for movie ID 18785 (attempt 3): HTTPSConnectionPool(host='api.themoviedb.org', port=443): Max retries exceeded with url: /3/movie/18785?api_key=9fb9d335431a9f6007701ac905fcd5e5 (Caused by NewConnectionError('<urllib3.connection.HTTPSConnection object at 0x7ff04508d0d0>: Failed to establish a new connection: [Errno -2] Name or service not known'))
[2024-12-24T06:06:34.500+0000] {subprocess.py:93} INFO - Failed to fetch details for movie ID 18785 after 3 attempts.
[2024-12-24T06:06:34.501+0000] {subprocess.py:93} INFO - Fetched data for page 14
[2024-12-24T06:06:34.501+0000] {subprocess.py:93} INFO - Attempt 1 failed for page 15: HTTPSConnectionPool(host='api.themoviedb.org', port=443): Max retries exceeded with url: /3/movie/popular?api_key=9fb9d335431a9f6007701ac905fcd5e5&page=15 (Caused by NewConnectionError('<urllib3.connection.HTTPSConnection object at 0x7ff04508d370>: Failed to establish a new connection: [Errno -2] Name or service not known'))
[2024-12-24T06:06:34.501+0000] {subprocess.py:93} INFO - Attempt 2 failed for page 15: HTTPSConnectionPool(host='api.themoviedb.org', port=443): Max retries exceeded with url: /3/movie/popular?api_key=9fb9d335431a9f6007701ac905fcd5e5&page=15 (Caused by NewConnectionError('<urllib3.connection.HTTPSConnection object at 0x7ff04508ddc0>: Failed to establish a new connection: [Errno -2] Name or service not known'))
[2024-12-24T06:06:34.502+0000] {subprocess.py:93} INFO - Attempt 3 failed for page 15: HTTPSConnectionPool(host='api.themoviedb.org', port=443): Max retries exceeded with url: /3/movie/popular?api_key=9fb9d335431a9f6007701ac905fcd5e5&page=15 (Caused by NewConnectionError('<urllib3.connection.HTTPSConnection object at 0x7ff04508dd90>: Failed to establish a new connection: [Errno -2] Name or service not known'))
[2024-12-24T06:06:34.503+0000] {subprocess.py:93} INFO - Failed to fetch data for page 15 after 3 attempts.
[2024-12-24T06:06:34.504+0000] {subprocess.py:93} INFO - Movie data with selected fields has been saved to /opt/***/DE_project/data/JSON/movies_data.json
[2024-12-24T06:06:34.527+0000] {subprocess.py:97} INFO - Command exited with return code 0
[2024-12-24T06:06:34.595+0000] {taskinstance.py:1400} INFO - Marking task as SUCCESS. dag_id=movie_etl_workflow, task_id=fetch_movie_data, execution_date=20241224T060455, start_date=20241224T060457, end_date=20241224T060634
[2024-12-24T06:06:34.662+0000] {local_task_job_runner.py:228} INFO - Task exited with return code 0
[2024-12-24T06:06:34.714+0000] {taskinstance.py:2784} INFO - 1 downstream tasks scheduled from follow-on schedule check
