[2024-12-24T06:12:29.775+0000] {taskinstance.py:1159} INFO - Dependencies all met for dep_context=non-requeueable deps ti=<TaskInstance: test.fetch_rating_data manual__2024-12-24T06:12:28.449758+00:00 [queued]>
[2024-12-24T06:12:29.801+0000] {taskinstance.py:1159} INFO - Dependencies all met for dep_context=requeueable deps ti=<TaskInstance: test.fetch_rating_data manual__2024-12-24T06:12:28.449758+00:00 [queued]>
[2024-12-24T06:12:29.801+0000] {taskinstance.py:1361} INFO - Starting attempt 1 of 2
[2024-12-24T06:12:29.853+0000] {taskinstance.py:1382} INFO - Executing <Task(BashOperator): fetch_rating_data> on 2024-12-24 06:12:28.449758+00:00
[2024-12-24T06:12:29.867+0000] {standard_task_runner.py:57} INFO - Started process 2033 to run task
[2024-12-24T06:12:29.874+0000] {standard_task_runner.py:84} INFO - Running: ['***', 'tasks', 'run', 'test', 'fetch_rating_data', 'manual__2024-12-24T06:12:28.449758+00:00', '--job-id', '204', '--raw', '--subdir', 'DAGS_FOLDER/movie_data_workflow.py', '--cfg-path', '/tmp/tmpj1qsqtjh']
[2024-12-24T06:12:29.878+0000] {standard_task_runner.py:85} INFO - Job 204: Subtask fetch_rating_data
[2024-12-24T06:12:29.911+0000] {warnings.py:109} WARNING - /home/***/.local/lib/python3.8/site-packages/***/settings.py:195: DeprecationWarning: The sql_alchemy_conn option in [core] has been moved to the sql_alchemy_conn option in [database] - the old setting has been used, but please update your config.
  SQL_ALCHEMY_CONN = conf.get("database", "SQL_ALCHEMY_CONN")

[2024-12-24T06:12:30.003+0000] {task_command.py:415} INFO - Running <TaskInstance: test.fetch_rating_data manual__2024-12-24T06:12:28.449758+00:00 [running]> on host 4170f75a0525
[2024-12-24T06:12:30.185+0000] {taskinstance.py:1660} INFO - Exporting env vars: AIRFLOW_CTX_DAG_OWNER='diinguyen' AIRFLOW_CTX_DAG_ID='test' AIRFLOW_CTX_TASK_ID='fetch_rating_data' AIRFLOW_CTX_EXECUTION_DATE='2024-12-24T06:12:28.449758+00:00' AIRFLOW_CTX_TRY_NUMBER='1' AIRFLOW_CTX_DAG_RUN_ID='manual__2024-12-24T06:12:28.449758+00:00'
[2024-12-24T06:12:30.189+0000] {subprocess.py:63} INFO - Tmp dir root location: /tmp
[2024-12-24T06:12:30.190+0000] {subprocess.py:75} INFO - Running command: ['/bin/bash', '-c', 'python3 /opt/***/DE_project/ETL/extract/API_rating_Themoviedb.py']
[2024-12-24T06:12:30.216+0000] {subprocess.py:86} INFO - Output:
[2024-12-24T06:12:49.788+0000] {local_task_job_runner.py:115} ERROR - Received SIGTERM. Terminating subprocesses
[2024-12-24T06:12:49.833+0000] {process_utils.py:131} INFO - Sending 15 to group 2033. PIDs of all processes in the group: [2036, 2033]
[2024-12-24T06:12:49.839+0000] {process_utils.py:86} INFO - Sending the signal 15 to group 2033
[2024-12-24T06:12:49.848+0000] {taskinstance.py:1632} ERROR - Received SIGTERM. Terminating subprocesses.
[2024-12-24T06:12:49.856+0000] {subprocess.py:104} INFO - Sending SIGTERM signal to process group
[2024-12-24T06:12:49.911+0000] {taskinstance.py:1943} ERROR - Task failed with exception
Traceback (most recent call last):
  File "/home/airflow/.local/lib/python3.8/site-packages/airflow/operators/bash.py", line 201, in execute
    result = self.subprocess_hook.run_command(
  File "/home/airflow/.local/lib/python3.8/site-packages/airflow/hooks/subprocess.py", line 91, in run_command
    for raw_line in iter(self.sub_process.stdout.readline, b""):
  File "/home/airflow/.local/lib/python3.8/site-packages/airflow/models/taskinstance.py", line 1634, in signal_handler
    raise AirflowException("Task received SIGTERM signal")
airflow.exceptions.AirflowException: Task received SIGTERM signal
[2024-12-24T06:12:49.930+0000] {taskinstance.py:1400} INFO - Marking task as UP_FOR_RETRY. dag_id=test, task_id=fetch_rating_data, execution_date=20241224T061228, start_date=20241224T061229, end_date=20241224T061249
[2024-12-24T06:12:49.959+0000] {standard_task_runner.py:104} ERROR - Failed to execute job 204 for task fetch_rating_data (Task received SIGTERM signal; 2033)
[2024-12-24T06:12:49.987+0000] {process_utils.py:79} INFO - Process psutil.Process(pid=2033, status='terminated', exitcode=1, started='06:12:29') (2033) terminated with exit code 1
[2024-12-24T06:12:49.998+0000] {process_utils.py:79} INFO - Process psutil.Process(pid=2036, status='terminated', started='06:12:30') (2036) terminated with exit code None
[2024-12-24T06:12:50.000+0000] {local_task_job_runner.py:228} INFO - Task exited with return code 143
[2024-12-24T06:12:50.068+0000] {taskinstance.py:2784} INFO - 0 downstream tasks scheduled from follow-on schedule check
