[2024-12-22T14:37:19.084+0000] {taskinstance.py:1159} INFO - Dependencies all met for dep_context=non-requeueable deps ti=<TaskInstance: movie_data_workflow.transform_data manual__2024-12-22T14:37:18.160283+00:00 [queued]>
[2024-12-22T14:37:19.095+0000] {taskinstance.py:1159} INFO - Dependencies all met for dep_context=requeueable deps ti=<TaskInstance: movie_data_workflow.transform_data manual__2024-12-22T14:37:18.160283+00:00 [queued]>
[2024-12-22T14:37:19.096+0000] {taskinstance.py:1361} INFO - Starting attempt 1 of 2
[2024-12-22T14:37:19.115+0000] {taskinstance.py:1382} INFO - Executing <Task(PythonOperator): transform_data> on 2024-12-22 14:37:18.160283+00:00
[2024-12-22T14:37:19.120+0000] {standard_task_runner.py:57} INFO - Started process 142 to run task
[2024-12-22T14:37:19.126+0000] {standard_task_runner.py:84} INFO - Running: ['***', 'tasks', 'run', 'movie_data_workflow', 'transform_data', 'manual__2024-12-22T14:37:18.160283+00:00', '--job-id', '11', '--raw', '--subdir', 'DAGS_FOLDER/movie_data_workflow.py', '--cfg-path', '/tmp/tmph8uitwkg']
[2024-12-22T14:37:19.128+0000] {standard_task_runner.py:85} INFO - Job 11: Subtask transform_data
[2024-12-22T14:37:19.151+0000] {warnings.py:109} WARNING - /home/***/.local/lib/python3.8/site-packages/***/settings.py:195: DeprecationWarning: The sql_alchemy_conn option in [core] has been moved to the sql_alchemy_conn option in [database] - the old setting has been used, but please update your config.
  SQL_ALCHEMY_CONN = conf.get("database", "SQL_ALCHEMY_CONN")

[2024-12-22T14:37:19.208+0000] {task_command.py:415} INFO - Running <TaskInstance: movie_data_workflow.transform_data manual__2024-12-22T14:37:18.160283+00:00 [running]> on host d2f34721e96e
[2024-12-22T14:37:19.307+0000] {taskinstance.py:1660} INFO - Exporting env vars: AIRFLOW_CTX_DAG_OWNER='diinguyen' AIRFLOW_CTX_DAG_ID='movie_data_workflow' AIRFLOW_CTX_TASK_ID='transform_data' AIRFLOW_CTX_EXECUTION_DATE='2024-12-22T14:37:18.160283+00:00' AIRFLOW_CTX_TRY_NUMBER='1' AIRFLOW_CTX_DAG_RUN_ID='manual__2024-12-22T14:37:18.160283+00:00'
[2024-12-22T14:37:19.439+0000] {taskinstance.py:1943} ERROR - Task failed with exception
Traceback (most recent call last):
  File "/home/airflow/.local/lib/python3.8/site-packages/airflow/operators/python.py", line 192, in execute
    return_value = self.execute_callable()
  File "/home/airflow/.local/lib/python3.8/site-packages/airflow/operators/python.py", line 209, in execute_callable
    return self.python_callable(*self.op_args, **self.op_kwargs)
  File "/opt/airflow/dags/movie_data_workflow.py", line 26, in transform_data
    subprocess.run(['python3', '/opt/airflow/DE_project/ETL/transform/tranform_moviedf.py'], check=True)
  File "/usr/local/lib/python3.8/subprocess.py", line 516, in run
    raise CalledProcessError(retcode, process.args,
subprocess.CalledProcessError: Command '['python3', '/opt/airflow/DE_project/ETL/transform/tranform_moviedf.py']' returned non-zero exit status 2.
[2024-12-22T14:37:19.454+0000] {taskinstance.py:1400} INFO - Marking task as UP_FOR_RETRY. dag_id=movie_data_workflow, task_id=transform_data, execution_date=20241222T143718, start_date=20241222T143719, end_date=20241222T143719
[2024-12-22T14:37:19.469+0000] {standard_task_runner.py:104} ERROR - Failed to execute job 11 for task transform_data (Command '['python3', '/opt/airflow/DE_project/ETL/transform/tranform_moviedf.py']' returned non-zero exit status 2.; 142)
[2024-12-22T14:37:19.511+0000] {local_task_job_runner.py:228} INFO - Task exited with return code 1
[2024-12-22T14:37:19.542+0000] {taskinstance.py:2784} INFO - 0 downstream tasks scheduled from follow-on schedule check
